Workbook

Sheet 1 · Vendor Profile
A2: 1 · Vendor Profile & Scope
B5: Assessment reference | C5: MTB-TPRM-2026-0417
B6: Vendor name | C6: CloudLedger Technologies Ltd
B7: Service / product | C7: OriginateCloud - cloud loan-origination and document-management SaaS platform
B8: Business process it supports | C8: Personal-loan and mortgage application origination, affordability checks, document collection and lending workflow management
B9: Data types held | C9: Customer full name, address, date of birth, contact details, income and employment data, bank statements, and scanned identity documents (passport / driving licence)
B10: Approx. records within 12 months | C10: 40000
B11: Is the process critical / important? | C11: Yes - supports a critical / important retail-lending process and holds customer personal and financial data
B12: Hosting & region(s) | C12: Amazon Web Services, eu-west-1 (Ireland); single region across multiple availability zones, with no secondary region configured
B13: Subprocessors (fourth parties) | C13: Amazon Web Services - hosting/storage (Ireland); VerifyID Ltd - identity verification (UK); MailRelay Inc. - transactional email (US); CloudLedger Support offshore centre - L1 customer support with full production access (outside UK/EEA)
B14: Certifications claimed | C14: SOC 2 Type II; ISO/IEC 27001
B15: Assessor name | C15: Adithyakrishnan Sureshbabu
B16: Assessment date | C16: 46227

Sheet 2 · Tiering
A2: 2 · Inherent Risk Tiering
B5: Inherent-risk factor | C5: Score 1-5 | D5: Weight | E5: Weighted
B6: Data sensitivity (PII, financial, special category) | C6: 5 | D6: 0.35 | E6: =C6*D6 -> 1.75
B7: Operational criticality (how critical / hard to pause) | C7: 5 | D7: 0.3 | E7: =C7*D7 -> 1.5
B8: Regulatory exposure (GDPR, DORA, sector rules) | C8: 5 | D8: 0.2 | E8: =C8*D8 -> 1
B9: System / network / data access granted | C9: 4 | D9: 0.15 | E9: =C9*D9 -> 0.6
B10: Weighted inherent-risk score | D10: =SUM(D6:D9) -> 1 | E10: =SUM(E6:E9) -> 4.85
B12: VENDOR TIER | C12: =IF(E10>=4,"CRITICAL",IF(E10>=3,"HIGH",IF(E10>=2,"MEDIUM","LOW"))) -> CRITICAL

Sheet 3 · Questionnaire
A2: 3 · Due Diligence Questionnaire
B5: Control | C5: Vendor claim (summary) | D5: Evidence ref | E5: Verdict | F5: Assessor note
B6: Section 1 · Governance & policy
B7: Documented, senior-approved infosec policy | C7: Yes, policy provided | D7: D4 | E7: Met | F7: AES-256 at rest confirmed in Q3.1. Leave verdict cells like this.
B8: Policy reviewed at least annually | C8: Yes, annual review | D8: D4 | E8: Not met | F8: D4 was last reviewed in January 2024, so the stated annual review cycle has not been met.
B9: Named security owner | C9: No dedicated owner; eng leadership | D9: Q1.3 | E9: Not met | F9: Q1.3 gives only general engineering oversight; D4 has no named owner and no dedicated security lead.
B10: Section 2 · Access control & identity
B11: MFA on customer application | C11: Yes | D11: SOC2 / Q2.1 | E11: Met | F11: D1 independently confirms MFA is enforced on the customer application.
B12: MFA on admin console & VPN | C12: Roadmap; VPN is password-only | D12: D1 / D3-H2 | E12: Not met | F12: D1 and D3-H2 confirm the admin console lacked MFA; VPN access is also password-only.
B13: Periodic access recertification | C13: Yes (claimed) | D13: D1 exceptions | E13: Not met | F13: D1 shows reviews exist, but 3 of 12 quarterly reviews were late and one leaver retained access for 14 days.
B14: No shared / generic admin accounts | C14: Some shared accounts used | D14: Q2.4 | E14: Not met | F14: Q2.4 confirms shared service/admin accounts are used, contrary to the control.
B15: Section 3 · Data protection & encryption
B16: Encryption at rest (AES-256) | C16: Yes | D16: Q3.1 | E16: Met | F16: Q3.1 and D7 confirm AWS-managed AES-256 encryption at rest.
B17: Encryption in transit (TLS 1.2+) | C17: Yes, customer traffic | D17: Q3.2 / D3-H1 | E17: Partially met | F17: Customer traffic uses TLS 1.2+, but D3-H1 found TLS 1.0/1.1 enabled on a legacy support endpoint.
B18: PII processed outside UK/EEA controlled | C18: Offshore support has access | D18: B / D7 | E18: Partially met | F18: Offshore access is declared, but D7 lacks attached SCCs and a transfer risk assessment.
B19: Approved transfer mechanism (SCCs) | C19: Referenced, not attached | D19: D7 | E19: Not met | F19: D7 names SCCs but they are not attached, and no transfer risk assessment is provided.
B20: Defined retention schedule | C20: 'As long as necessary' | D20: D7 | E20: Not met | F20: D7 says only 'as long as necessary'; no defined retention periods are provided.
B21: Section 4 · Vulnerability & patch mgmt
B22: Regular vulnerability scanning | C22: Yes, monthly | D22: Q4.1 | E22: Partially met | F22: Monthly scanning is claimed in Q4.1, but no scan report or other supporting evidence was supplied.
B23: Annual independent pen test | C23: Yes (but 14 months old) | D23: D3 | E23: Not met | F23: D3 confirms an independent test, but it is 14 months old and external unauthenticated test.
B24: Pen-test findings remediated in SLA | C24: 2 High findings still open | D24: D3 | E24: Not met | F24: D3 shows findings H1 and H2 remain open past the 90-day remediation SLA.
B25: Section 5 · Secure development
B26: Secure SDLC with code review | C26: Yes, PR review | D26: Q5.1 | E26: Not met | F26: Q5.1 claims pull-request review, but no SDLC policy, samples or independent evidence were supplied.
B27: Environments separated | C27: Yes | D27: Q5.2 | E27: Not met | F27: Q5.2 claims logical separation in AWS, but no architecture or configuration evidence was supplied.
B28: Section 6 · Logging, monitoring & IR
B29: Documented incident response plan | C29: Yes | D29: D5 | E29: Met | F29: D5 documents severity levels, escalation, containment, eradication and recovery steps.
B30: Committed breach-notification timeframe | C30: 'Promptly', no SLA | D30: D5 / D7 | E30: Not met | F30: D5 and D7 say 'promptly' or 'without undue delay' but set no fixed breach-notification SLA.
B31: IR plan tested in last 12 months | C31: No record provided | D31: D5 | E31: Not met | F31: No record of a tabletop or live exercise in the last 12 months is provided
B32: Section 7 · Business continuity & DR
B33: Documented RTO / RPO | C33: RTO 8h / RPO 4h | D33: D6 | E33: Met | F33: D6 documents an RTO of 8 hours and an RPO of 4 hours.
B34: Multi-region failover | C34: Single region eu-west-1 | D34: D6 | E34: Not met | F34: D6 confirms multi-AZ operation in one region only, with no secondary-region failover.
B35: DR test in last 12 months | C35: Last test Feb 2024 | D35: D6 | E35: Not met | F35: D6 shows the last test was partial in February 2024; no full test occurred within 12 months.
B36: Section 8 · Fourth-party management
B37: Subprocessor list maintained | C37: Yes | D37: B | E37: Met | F37: Section B provides a complete declared subprocessor list; D1 CUECs also reference notification review.
B38: Security obligations flowed down & assessed | C38: Not evidenced for offshore | D38: Q8.2 | E38: Not met | F38: Q8.2 provides no evidence that obligations are flowed down or that offshore support is assessed.
B39: Section 9 · Compliance & assurance
B40: Current SOC 2 (type & scope adequate) | C40: Type II, Security only, stale | D40: D1 | E40: Partially met | F40: D1 is Type II, but coverage ended March 2025, only Security was in scope, offshore support was excluded, and exceptions remain.
B41: Current ISO 27001 (scope adequate) | C41: Excludes offshore; expires soon | D41: D2 | E41: Partially met | F41: D2 remains valid to August 2026, but surveillance is pending and offshore support is excluded from scope.
B42: Right to audit granted | C42: No, SOC 2 offered instead | D42: D7 | E42: Not met | F42: D7 confirms there is no contractual right to audit; the SOC 2 report is offered instead.
B43: Section 10 · Physical & personnel security
...

Sheet 4 · Findings
A2: 4 · Findings Register
B5: ID | C5: Domain | D5: Finding | E5: Owner | F5: Likelihood 1-5 | G5: Impact 1-5 | H5: Score | I5: Rating | J5: Recommendation | K5: Due date | L5: Status
B6: F1 | C6: BC / DR (Section 7) | D6: No evidenced DR/failover test in >12 months; single AWS region, no cross-region failover. | E6: Vendor | F6: 4 | G6: 5 | H6: =IF(OR(F6="",G6=""),"",F6*G6) -> 20 | I6: =IF(H6="","",IF(H6>=15,"Critical",IF(H6>=10,"High",IF(H6>=5,"Medium","Low")))) -> Critical | J6: Configure cross-region failover; run and evidence a full DR test. | K6: 30 days | L6: Open
B7: F2 | C7: Data protection (Section 3) | D7: Offshore support has full production access to customer PII without attached SCCs or a documented transfer risk assessment. | E7: Bank | F7: 4 | G7: 5 | H7: 20 | I7: Critical | J7: Attach approved SCCs, complete a transfer risk assessment, and restrict offshore production access to least privilege. | K7: Before go-live; 23 Aug 2026 | L7: Open
B8: F3 | C8: Access control (Section 2) | D8: Administrative and VPN access lacks MFA; shared admin accounts are used, and access reviews/deprovisioning were not consistently timely. | E8: Vendor | F8: 3 | G8: 4 | H8: 12 | I8: High | J8: Enforce MFA for admin/VPN access, remove shared privileged accounts, and evidence timely reviews and deprovisioning. | K8: 46257 | L8: Open
B9: F4 | C9: Vulnerability management (Section 4) | D9: The penetration test is overdue and limited in scope; two High findings, including legacy TLS and internet-exposed admin access, remain past SLA. | E9: Vendor | F9: 3 | G9: 4 | H9: 12 | I9: High | J9: Close H1/H2, commission a current authenticated/internal and external test, and provide monthly vulnerability-scan evidence. | K9: 46257 | L9: Open
B10: F5 | C10: Assurance (Section 9) | D10: SOC 2 evidence is stale and Security-only, while both SOC 2 and ISO 27001 exclude the offshore support operation; ISO surveillance is pending. | E10: Vendor | F10: 3 | G10: 4 | H10: 12 | I10: High | J10: Provide current assurance covering relevant criteria and offshore support, plus renewed ISO certification/surveillance evidence. | K10: 46257 | L10: Open
B11: F6 | C11: Governance (Section 1) | D11: The information-security policy is overdue for review, lacks senior-management approval and a document owner, and no named security lead is evidenced. | E11: Vendor | F11: 2 | G11: 3 | H11: 6 | I11: Medium | J11: Appoint a named security owner and reapprove the policy with complete document control and an annual review record. | K11: 46317 | L11: Open
B12: F7 | C12: Incident response (Section 6) | D12: The incident-response plan has no evidenced exercise in the last 12 months and no fixed client breach-notification commitment. | E12: Vendor | F12: 2 | G12: 4 | H12: 8 | I12: Medium | J12: Run and evidence a tabletop exercise and agree a fixed breach-notification SLA in the contract. | K12: 46317 | L12: Open
B13: F8 | C13: Control evidence (Sections 4, 5, 10) | D13: Monthly scanning, secure code review, environment separation, and personnel screening are claimed but not supported by evidence. | E13: Vendor | F13: 2 | G13: 3 | H13: 6 | I13: Medium | J13: Provide policies, configurations, samples and operating evidence for scanning, SDLC, environment separation and staff screening. | K13: 46317 | L13: Open
B14: F9 | C14: Contract / fourth parties (Sections 3, 8, 9) | D14: Contract and supplier controls lack a right to audit, defined retention periods, and evidence that obligations are flowed down to offshore support. | E14: Bank | F14: 2 | G14: 4 | H14: 8 | I14: Medium | J14: Add right-to-audit and retention terms, require security obligations to flow down, and obtain offshore due-diligence evidence. | K14: Before contract signature | L14: Open
H15: =IF(OR(F15="",G15=""),"",F15*G15) | I15: =IF(H15="","",IF(H15>=15,"Critical",IF(H15>=10,"High",IF(H15>=5,"Medium","Low"))))
H16: =IF(OR(F16="",G16=""),"",F16*G16) | I16: =IF(H16="","",IF(H16>=15,"Critical",IF(H16>=10,"High",IF(H16>=5,"Medium","Low"))))
H17: =IF(OR(F17="",G17=""),"",F17*G17) | I17: =IF(H17="","",IF(H17>=15,"Critical",IF(H17>=10,"High",IF(H17>=5,"Medium","Low"))))
H18: =IF(OR(F18="",G18=""),"",F18*G18) | I18: =IF(H18="","",IF(H18>=15,"Critical",IF(H18>=10,"High",IF(H18>=5,"Medium","Low"))))
H19: =IF(OR(F19="",G19=""),"",F19*G19) | I19: =IF(H19="","",IF(H19>=15,"Critical",IF(H19>=10,"High",IF(H19>=5,"Medium","Low"))))
H20: =IF(OR(F20="",G20=""),"",F20*G20) | I20: =IF(H20="","",IF(H20>=15,"Critical",IF(H20>=10,"High",IF(H20>=5,"Medium","Low"))))
H21: =IF(OR(F21="",G21=""),"",F21*G21) | I21: =IF(H21="","",IF(H21>=15,"Critical",IF(H21>=10,"High",IF(H21>=5,"Medium","Low"))))
H22: =IF(OR(F22="",G22=""),"",F22*G22) | I22: =IF(H22="","",IF(H22>=15,"Critical",IF(H22>=10,"High",IF(H22>=5,"Medium","Low"))))
H23: =IF(OR(F23="",G23=""),"",F23*G23) | I23: =IF(H23="","",IF(H23>=15,"Critical",IF(H23>=10,"High",IF(H23>=5,"Medium","Low"))))
H24: =IF(OR(F24="",G24=""),"",F24*G24) | I24: =IF(H24="","",IF(H24>=15,"Critical",IF(H24>=10,"High",IF(H24>=5,"Medium","Low"))))
H25: =IF(OR(F25="",G25=""),"",F25*G25) | I25: =IF(H25="","",IF(H25>=15,"Critical",IF(H25>=10,"High",IF(H25>=5,"Medium","Low"))))

Sheet 5 · Risk Matrix
A2: 5 · Risk Rating Matrix (Likelihood x Impact)
B5: Impact ↓ / Likelihood → | C5: 1 Rare | D5: 2 Unlikely | E5: 3 Possible | F5: 4 Likely | G5: 5 Almost certain
B6: 5 Severe | C6: 5 | D6: 10 | E6: 15 | F6: 20 | G6: 25
B7: 4 Major | C7: 4 | D7: 8 | E7: 12 | F7: 16 | G7: 20
B8: 3 Moderate | C8: 3 | D8: 6 | E8: 9 | F8: 12 | G8: 15
B9: 2 Minor | C9: 2 | D9: 4 | E9: 6 | F9: 8 | G9: 10
B10: 1 Negligible | C10: 1 | D10: 2 | E10: 3 | F10: 4 | G10: 5
B13: Rating bands
B14: Low (1-4)
B15: Medium (5-9)
B16: High (10-14)
B17: Critical (15-25)

Sheet 6 · Decision
A2: 6 · Assessment Decision
B5: Vendor tier | C5: ='2 · Tiering'!C12 -> CRITICAL
B6: Critical findings | C6: =COUNTIF('4 · Findings'!I6:I25,"Critical") -> 2
B7: High findings | C7: =COUNTIF('4 · Findings'!I6:I25,"High") -> 3
B8: Medium findings | C8: =COUNTIF('4 · Findings'!I6:I25,"Medium") -> 4
B9: Low findings | C9: =COUNTIF('4 · Findings'!I6:I25,"Low") -> 0
B10: Overall residual risk (your view) | C10: Critical
B11: Within the bank's risk appetite? | C11: No
B12: Recommendation | C12: Approve with conditions
B13: Conditions / remediation deadline | C13: Do not go live until F1 and F2 are closed and re-evidenced. Close or formally remediate F3-F5 within 30 days; complete F6-F9 within 90 days or before contract signature where stated.
B14: Accountable risk owner | C14: Head of Retail Lending (accountable business risk owner), with Head of Risk oversight
B15: Decision date | C15: 46227
